Workbook

Sheet Hypothèses
A1: SOLAR WRAP — Hypothèses du modèle
A2: Prévisionnel 2027–2033 | cellules bleues = hypothèses modifiables | jaune = hypothèses critiques à valider | B2: Prévisionnel 2027–2033 | cellules bleues = hypothèses modifiables | jaune = hypothèses critiques à valider | C2: Prévisionnel 2027–2033 | cellules bleues = hypothèses modifiables | jaune = hypothèses critiques à valider | D2: Prévisionnel 2027–2033 | cellules bleues = hypothèses modifiables | jaune = hypothèses critiques à valider | E2: Prévisionnel 2027–2033 | cellules bleues = hypothèses modifiables | jaune = hypothèses critiques à valider | F2: Prévisionnel 2027–2033 | cellules bleues = hypothèses modifiables | jaune = hypothèses critiques à valider | G2: Prévisionnel 2027–2033 | cellules bleues = hypothèses modifiables | jaune = hypothèses critiques à valider | H2: Prévisionnel 2027–2033 | cellules bleues = hypothèses modifiables | jaune = hypothèses critiques à valider | I2: Prévisionnel 2027–2033 | cellules bleues = hypothèses modifiables | jaune = hypothèses critiques à valider
A3: A. Hypothèses générales | B3: A. Hypothèses générales | C3: A. Hypothèses générales | D3: A. Hypothèses générales | E3: A. Hypothèses générales | F3: A. Hypothèses générales | G3: A. Hypothèses générales | H3: A. Hypothèses générales | I3: A. Hypothèses générales
A4: Hypothèse | B4: Valeur | C4: Unité | D4: Nature | E4: Source / justification
A5: Taux d'IS | B5: 0.25 | C5: % | D5: Source externe | E5: https://entreprendre.service-public.gouv.fr/vosdroits/F23575
A6: DSO clients | B6: 45 | C6: jours | D6: Hypothèse management | E6: À valider avec contrats flotte
A7: Stock moyen | B7: 60 | C7: jours de COGS hardware | D7: Hypothèse management | E7: Externalisation industrielle visée
A8: DPO fournisseurs | B8: 45 | C8: jours | D8: Hypothèse management | E8: À négocier
A9: Attrition parc installé | B9: 0.03 | C9: % / an | D9: Hypothèse management | E9: Proxy remplacement/fin de vie
A10: Marge brute services | B10: 0.55 | C10: % | D10: Hypothèse management | E10: Ingénierie, intégration, certification
A11: Marge brute SaaS | B11: 0.85 | C11: % | D11: Hypothèse management | E11: SOLAR CONTROL
A12: Trésorerie initiale | B12: 250000 | C12: € | D12: Hypothèse management | E12: Capital de départ du modèle
A13: Durée amortissement CAPEX | B13: 5 | C13: années | D13: Hypothèse modèle | E13: Amortissement linéaire simplifié
A15: B. Économie client — cas de référence camion / remorque frigorifique | B15: B. Économie client — cas de référence camion / remorque frigorifique | C15: B. Économie client — cas de référence camion / remorque frigorifique | D15: B. Économie client — cas de référence camion / remorque frigorifique | E15: B. Économie client — cas de référence camion / remorque frigorifique | F15: B. Économie client — cas de référence camion / remorque frigorifique | G15: B. Économie client — cas de référence camion / remorque frigorifique | H15: B. Économie client — cas de référence camion / remorque frigorifique | I15: B. Économie client — cas de référence camion / remorque frigorifique
A16: Hypothèse | B16: Valeur | C16: Unité | D16: Nature | E16: Source / justification
A17: Économie de gazole | B17: 1500 | C17: L/an | D17: Source externe | E17: Fraunhofer ISE: 1 500–2 100 L/an sur camion 40 t (référence historique)
A18: Valeur économique du gazole | B18: 1.5 | C18: €/L | D18: Hypothèse prudente normalisée | E18: Volatilité élevée; inférieur aux prix pompe observés fin oct. 2026
A19: Autres économies | B19: 250 | C19: €/an | D19: Hypothèse management | E19: Batterie auxiliaire / maintenance / disponibilité
A20: Facteur émission gazole B7 | B20: 3.1 | C20: kgCO2e/L | D20: Source externe | E20: ADEME / Base Empreinte, ordre de grandeur total amont + combustion
A21: Payback client cible | B21: 5 | C21: années | D21: Objectif management | E21: Doit rester <5 ans
A23: C. Hypothèses annuelles — scénario central | B23: C. Hypothèses annuelles — scénario central | C23: C. Hypothèses annuelles — scénario central | D23: C. Hypothèses annuelles — scénario central | E23: C. Hypothèses annuelles — scénario central | F23: C. Hypothèses annuelles — scénario central | G23: C. Hypothèses annuelles — scénario central | H23: C. Hypothèses annuelles — scénario central | I23: C. Hypothèses annuelles — scénario central
A24: Hypothèse | B24: Unité | C24: 2027 | D24: 2028 | E24: 2029 | F24: 2030 | G24: 2031 | H24: 2032 | I24: 2033
A25: Comptes flotte actifs | B25: clients | C25: 3 | D25: 10 | E25: 25 | F25: 50 | G25: 90 | H25: 140 | I25: 200
A26: Déploiement annuel moyen / compte | B26: véhicules | C26: 5 | D26: 12 | E26: 18 | F26: 22 | G26: 24.444444 | H26: 25 | I26: 25
A27: Prix moyen kit + installation | B27: €/véhicule | C27: 8000 | D27: 10500 | E27: 10300 | F27: 10100 | G27: 9900 | H27: 9700 | I27: 9500
A28: COGS hardware / véhicule | B28: €/véhicule | C28: 8500 | D28: 6500 | E28: 6100 | F28: 5700 | G28: 5400 | H28: 5100 | I28: 4900
A29: Taux d'attachement SOLAR CONTROL | B29: % | C29: 0 | D29: 0.75 | E29: 0.8 | F29: 0.82 | G29: 0.84 | H29: 0.85 | I29: 0.86
A30: Abonnement SOLAR CONTROL | B30: €/véhicule/an | C30: 0 | D30: 360 | E30: 360 | F30: 370 | G30: 380 | H30: 390 | I30: 400
A31: Revenus services / ingénierie | B31: €/an | C31: 0 | D31: 50000 | E31: 150000 | F31: 300000 | G31: 500000 | H31: 700000 | I31: 900000
A32: Effectif moyen | B32: ETP | C32: 5 | D32: 8 | E32: 13 | F32: 22 | G32: 35 | H32: 50 | I32: 65
A33: Coût chargé moyen / ETP | B33: €/ETP/an | C33: 75000 | D33: 78000 | E33: 80000 | F33: 82000 | G33: 84000 | H33: 86000 | I33: 88000
A34: R&D hors masse salariale | B34: €/an | C34: 500000 | D34: 700000 | E34: 800000 | F34: 900000 | G34: 1000000 | H34: 1200000 | I34: 1400000
A35: Sales, Marketing & expansion internationale | B35: €/an | C35: 75000 | D35: 250000 | E35: 600000 | F35: 1100000 | G35: 1800000 | H35: 2600000 | I35: 3400000
... A38: Financement externe prévu | B38: €/an | C38: 2000000 | D38: 2500000 | E38: 1500000 | F38: 0 | G38: 0 | H38: 0 | I38: 0

Sheet Ventes
A1: SOLAR WRAP — Construction du chiffre d'affaires
A2: Volumes = comptes flotte × déploiement annuel moyen | SaaS calculé sur parc actif moyen | B2: Volumes = comptes flotte × déploiement annuel moyen | SaaS calculé sur parc actif moyen | C2: Volumes = comptes flotte × déploiement annuel moyen | SaaS calculé sur parc actif moyen | D2: Volumes = comptes flotte × déploiement annuel moyen | SaaS calculé sur parc actif moyen | E2: Volumes = comptes flotte × déploiement annuel moyen | SaaS calculé sur parc actif moyen | F2: Volumes = comptes flotte × déploiement annuel moyen | SaaS calculé sur parc actif moyen | G2: Volumes = comptes flotte × déploiement annuel moyen | SaaS calculé sur parc actif moyen | H2: Volumes = comptes flotte × déploiement annuel moyen | SaaS calculé sur parc actif moyen | I2: Volumes = comptes flotte × déploiement annuel moyen | SaaS calculé sur parc actif moyen
A3: Prévision commerciale | B3: Prévision commerciale | C3: Prévision commerciale | D3: Prévision commerciale | E3: Prévision commerciale | F3: Prévision commerciale | G3: Prévision commerciale | H3: Prévision commerciale | I3: Prévision commerciale
A4: Indicateur | B4: Unité | C4: 2027 | D4: 2028 | E4: 2029 | F4: 2030 | G4: 2031 | H4: 2032 | I4: 2033
A5: Comptes flotte actifs | B5: clients | C5: =Hypothèses!C25 -> 3 | D5: =Hypothèses!D25 -> 10 | E5: =Hypothèses!E25 -> 25 | F5: =Hypothèses!F25 -> 50 | G5: =Hypothèses!G25 -> 90 | H5: =Hypothèses!H25 -> 140 | I5: =Hypothèses!I25 -> 200
A6: Déploiement annuel moyen / compte | B6: véhicules | C6: =Hypothèses!C26 -> 5 | D6: =Hypothèses!D26 -> 12 | E6: =Hypothèses!E26 -> 18 | F6: =Hypothèses!F26 -> 22 | G6: =Hypothèses!G26 -> 24.444444 | H6: =Hypothèses!H26 -> 25 | I6: =Hypothèses!I26 -> 25
A7: Unités vendues | B7: véhicules | C7: =ROUND(C5*C6,0) -> 15 | D7: =ROUND(D5*D6,0) -> 120 | E7: =ROUND(E5*E6,0) -> 450 | F7: =ROUND(F5*F6,0) -> 1100 | G7: =ROUND(G5*G6,0) -> 2200 | H7: =ROUND(H5*H6,0) -> 3500 | I7: =ROUND(I5*I6,0) -> 5000
A8: Prix moyen hardware | B8: €/véhicule | C8: =Hypothèses!C27 -> 8000 | D8: =Hypothèses!D27 -> 10500 | E8: =Hypothèses!E27 -> 10300 | F8: =Hypothèses!F27 -> 10100 | G8: =Hypothèses!G27 -> 9900 | H8: =Hypothèses!H27 -> 9700 | I8: =Hypothèses!I27 -> 9500
A9: CA hardware | B9: € | C9: =C7*C8 -> 120000 | D9: =D7*D8 -> 1260000 | E9: =E7*E8 -> 4635000 | F9: =F7*F8 -> 11110000 | G9: =G7*G8 -> 21780000 | H9: =H7*H8 -> 33950000 | I9: =I7*I8 -> 47500000
A10: Parc actif début | B10: véhicules | C10: =0 -> 0 | D10: =C12 -> 15 | E10: =D12 -> 134.55 | F10: =E12 -> 580.5135 | G10: =F12 -> 1663.0981 | H10: =G12 -> 3813.2052 | I10: =H12 -> 7198.809
A11: Sorties / attrition | B11: véhicules | C11: =C10*Hypothèses!$B$9 -> 0 | D11: =D10*Hypothèses!$B$9 -> 0.45 | E11: =E10*Hypothèses!$B$9 -> 4.0365 | F11: =F10*Hypothèses!$B$9 -> 17.415405 | G11: =G10*Hypothèses!$B$9 -> 49.892943 | H11: =H10*Hypothèses!$B$9 -> 114.39615 | I11: =I10*Hypothèses!$B$9 -> 215.96427
A12: Parc actif fin | B12: véhicules | C12: =C10-C11+C7 -> 15 | D12: =D10-D11+D7 -> 134.55 | E12: =E10-E11+E7 -> 580.5135 | F12: =F10-F11+F7 -> 1663.0981 | G12: =G10-G11+G7 -> 3813.2052 | H12: =H10-H11+H7 -> 7198.809 | I12: =I10-I11+I7 -> 11982.845
A13: Parc actif moyen | B13: véhicules | C13: =(C10+C12)/2 -> 7.5 | D13: =(D10+D12)/2 -> 74.775 | E13: =(E10+E12)/2 -> 357.53175 | F13: =(F10+F12)/2 -> 1121.8058 | G13: =(G10+G12)/2 -> 2738.1516 | H13: =(H10+H12)/2 -> 5506.0071 | I13: =(I10+I12)/2 -> 9590.8269
A14: Taux attachement SaaS | B14: % | C14: =Hypothèses!C29 -> 0 | D14: =Hypothèses!D29 -> 0.75 | E14: =Hypothèses!E29 -> 0.8 | F14: =Hypothèses!F29 -> 0.82 | G14: =Hypothèses!G29 -> 0.84 | H14: =Hypothèses!H29 -> 0.85 | I14: =Hypothèses!I29 -> 0.86
A15: Fee SaaS annuel | B15: €/véhicule | C15: =Hypothèses!C30 -> 0 | D15: =Hypothèses!D30 -> 360 | E15: =Hypothèses!E30 -> 360 | F15: =Hypothèses!F30 -> 370 | G15: =Hypothèses!G30 -> 380 | H15: =Hypothèses!H30 -> 390 | I15: =Hypothèses!I30 -> 400
A16: CA SOLAR CONTROL | B16: € | C16: =C13*C14*C15 -> 0 | D16: =D13*D14*D15 -> 20189.25 | E16: =E13*E14*E15 -> 102969.14 | F16: =F13*F14*F15 -> 340355.88 | G16: =G13*G14*G15 -> 874018 | H16: =H13*H14*H15 -> 1825241.3 | I16: =I13*I14*I15 -> 3299244.4
A17: CA services / intégration | B17: € | C17: =Hypothèses!C31 -> 0 | D17: =Hypothèses!D31 -> 50000 | E17: =Hypothèses!E31 -> 150000 | F17: =Hypothèses!F31 -> 300000 | G17: =Hypothèses!G31 -> 500000 | H17: =Hypothèses!H31 -> 700000 | I17: =Hypothèses!I31 -> 900000
A18: CHIFFRE D'AFFAIRES TOTAL | B18: € | C18: =SUM(C9,C16,C17) -> 120000 | D18: =SUM(D9,D16,D17) -> 1330189.2 | E18: =SUM(E9,E16,E17) -> 4887969.1 | F18: =SUM(F9,F16,F17) -> 11750356 | G18: =SUM(G9,G16,G17) -> 23154018 | H18: =SUM(H9,H16,H17) -> 36475241 | I18: =SUM(I9,I16,I17) -> 51699244

Sheet Unit Economics
A1: SOLAR WRAP — Unit Economics & ROI client
A2: Cas de référence : camion / remorque frigorifique | objectifs à confirmer par prototype et devis fournisseurs | B2: Cas de référence : camion / remorque frigorifique | objectifs à confirmer par prototype et devis fournisseurs | C2: Cas de référence : camion / remorque frigorifique | objectifs à confirmer par prototype et devis fournisseurs | D2: Cas de référence : camion / remorque frigorifique | objectifs à confirmer par prototype et devis fournisseurs | E2: Cas de référence : camion / remorque frigorifique | objectifs à confirmer par prototype et devis fournisseurs | F2: Cas de référence : camion / remorque frigorifique | objectifs à confirmer par prototype et devis fournisseurs | G2: Cas de référence : camion / remorque frigorifique | objectifs à confirmer par prototype et devis fournisseurs | H2: Cas de référence : camion / remorque frigorifique | objectifs à confirmer par prototype et devis fournisseurs | I2: Cas de référence : camion / remorque frigorifique | objectifs à confirmer par prototype et devis fournisseurs
A3: A. ROI client — scénario prudent | B3: A. ROI client — scénario prudent | C3: A. ROI client — scénario prudent | D3: A. ROI client — scénario prudent | E3: A. ROI client — scénario prudent | F3: A. ROI client — scénario prudent | G3: A. ROI client — scénario prudent | H3: A. ROI client — scénario prudent | I3: A. ROI client — scénario prudent
A4: Indicateur | B4: Unité | C4: Valeur
A5: Prix client du système | B5: € | C5: =Hypothèses!D27 -> 10500
A6: Économie gazole | B6: L/an | C6: =Hypothèses!$B$17 -> 1500
A7: Valeur du gazole | B7: €/L | C7: =Hypothèses!$B$18 -> 1.5
A8: Économie carburant | B8: €/an | C8: =C6*C7 -> 2250
A9: Autres économies | B9: €/an | C9: =Hypothèses!$B$19 -> 250
A10: Économies annuelles totales | B10: €/an | C10: =SUM(C8,C9) -> 2500
A11: Payback client | B11: années | C11: =C5/C10 -> 4.2
A12: CO2e évité | B12: tCO2e/an | C12: =C6*Hypothèses!$B$20/1000 -> 4.65
A13: Économies brutes sur 10 ans | B13: € | C13: =C10*10 -> 25000
A14: Valeur créée / prix système | B14: x | C14: =C13/C5 -> 2.3809524
A16: B. Économie unitaire SOLAR WRAP | B16: B. Économie unitaire SOLAR WRAP | C16: B. Économie unitaire SOLAR WRAP | D16: B. Économie unitaire SOLAR WRAP | E16: B. Économie unitaire SOLAR WRAP | F16: B. Économie unitaire SOLAR WRAP | G16: B. Économie unitaire SOLAR WRAP | H16: B. Économie unitaire SOLAR WRAP | I16: B. Économie unitaire SOLAR WRAP
A17: Indicateur | B17: Unité | C17: 2028 commercial
A18: Prix moyen hardware | B18: €/véhicule | C18: =Hypothèses!D27 -> 10500
A19: COGS hardware | B19: €/véhicule | C19: =Hypothèses!D28 -> 6500
A20: Marge brute hardware | B20: €/véhicule | C20: =C18-C19 -> 4000
A21: Marge brute hardware | B21: % | C21: =C20/C18 -> 0.38095238
A22: Fee SaaS annuel | B22: €/véhicule | C22: =Hypothèses!D30 -> 360
A23: Marge brute SaaS annuelle | B23: €/véhicule | C23: =C22*Hypothèses!$B$11 -> 306
A24: Contribution 5 ans SaaS | B24: €/véhicule | C24: =C23*5 -> 1530
A25: Contribution client 5 ans | B25: €/véhicule | C25: =C20+C24 -> 5530
A27: C. Seuil de rentabilité opérationnel | B27: C. Seuil de rentabilité opérationnel | C27: C. Seuil de rentabilité opérationnel | D27: C. Seuil de rentabilité opérationnel | E27: C. Seuil de rentabilité opérationnel | F27: C. Seuil de rentabilité opérationnel | G27: C. Seuil de rentabilité opérationnel | H27: C. Seuil de rentabilité opérationnel | I27: C. Seuil de rentabilité opérationnel
A28: Indicateur | B28: Unité | C28: 2030
A29: OPEX fixes cash | B29: € | C29: ='P&L'!F18*1000 -> 4304000
A30: Marge unitaire hardware | B30: €/véhicule | C30: =Hypothèses!F27-Hypothèses!F28 -> 4400
A31: Marge brute SaaS + services | B31: € | C31: =('P&L'!F5*1000*Hypothèses!$B$11)+('P&L'!F6*1000*Hypothèses!$B$10) -> 454302.5
A32: Unités de break-even | B32: véhicules | C32: =(C29-C31)/C30 -> 874.93125
A33: Unités prévues | B33: véhicules | C33: =Ventes!F7 -> 1100
A34: Marge de sécurité | B34: % | C34: =(C33-C32)/C33 -> 0.20460795

Sheet P&L
A1: SOLAR WRAP — Compte de résultat prévisionnel
A2: Montants en k€ | modèle central | pertes fiscales reportées simplifiées | B2: Montants en k€ | modèle central | pertes fiscales reportées simplifiées | C2: Montants en k€ | modèle central | pertes fiscales reportées simplifiées | D2: Montants en k€ | modèle central | pertes fiscales reportées simplifiées | E2: Montants en k€ | modèle central | pertes fiscales reportées simplifiées | F2: Montants en k€ | modèle central | pertes fiscales reportées simplifiées | G2: Montants en k€ | modèle central | pertes fiscales reportées simplifiées | H2: Montants en k€ | modèle central | pertes fiscales reportées simplifiées | I2: Montants en k€ | modèle central | pertes fiscales reportées simplifiées
A3: Compte de résultat | B3: Unité | C3: 2027 | D3: 2028 | E3: 2029 | F3: 2030 | G3: 2031 | H3: 2032 | I3: 2033
A4: CA hardware | B4: k€ | C4: =Ventes!C9/1000 -> 120 | D4: =Ventes!D9/1000 -> 1260 | E4: =Ventes!E9/1000 -> 4635 | F4: =Ventes!F9/1000 -> 11110 | G4: =Ventes!G9/1000 -> 21780 | H4: =Ventes!H9/1000 -> 33950 | I4: =Ventes!I9/1000 -> 47500
A5: CA SOLAR CONTROL | B5: k€ | C5: =Ventes!C16/1000 -> 0 | D5: =Ventes!D16/1000 -> 20.18925 | E5: =Ventes!E16/1000 -> 102.96914 | F5: =Ventes!F16/1000 -> 340.35588 | G5: =Ventes!G16/1000 -> 874.018 | H5: =Ventes!H16/1000 -> 1825.2413 | I5: =Ventes!I16/1000 -> 3299.2444
A6: CA services / intégration | B6: k€ | C6: =Ventes!C17/1000 -> 0 | D6: =Ventes!D17/1000 -> 50 | E6: =Ventes!E17/1000 -> 150 | F6: =Ventes!F17/1000 -> 300 | G6: =Ventes!G17/1000 -> 500 | H6: =Ventes!H17/1000 -> 700 | I6: =Ventes!I17/1000 -> 900
A7: CHIFFRE D'AFFAIRES | B7: k€ | C7: =SUM(C4:C6) -> 120 | D7: =SUM(D4:D6) -> 1330.1892 | E7: =SUM(E4:E6) -> 4887.9691 | F7: =SUM(F4:F6) -> 11750.356 | G7: =SUM(G4:G6) -> 23154.018 | H7: =SUM(H4:H6) -> 36475.241 | I7: =SUM(I4:I6) -> 51699.244
A8: COGS hardware | B8: k€ | C8: =Ventes!C7*Hypothèses!C28/1000 -> 127.5 | D8: =Ventes!D7*Hypothèses!D28/1000 -> 780 | E8: =Ventes!E7*Hypothèses!E28/1000 -> 2745 | F8: =Ventes!F7*Hypothèses!F28/1000 -> 6270 | G8: =Ventes!G7*Hypothèses!G28/1000 -> 11880 | H8: =Ventes!H7*Hypothèses!H28/1000 -> 17850 | I8: =Ventes!I7*Hypothèses!I28/1000 -> 24500
A9: COGS SaaS | B9: k€ | C9: =C5*(1-Hypothèses!$B$11) -> 0 | D9: =D5*(1-Hypothèses!$B$11) -> 3.0283875 | E9: =E5*(1-Hypothèses!$B$11) -> 15.445372 | F9: =F5*(1-Hypothèses!$B$11) -> 51.053382 | G9: =G5*(1-Hypothèses!$B$11) -> 131.1027 | H9: =H5*(1-Hypothèses!$B$11) -> 273.7862 | I9: =I5*(1-Hypothèses!$B$11) -> 494.88667
A10: COGS services | B10: k€ | C10: =C6*(1-Hypothèses!$B$10) -> 0 | D10: =D6*(1-Hypothèses!$B$10) -> 22.5 | E10: =E6*(1-Hypothèses!$B$10) -> 67.5 | F10: =F6*(1-Hypothèses!$B$10) -> 135 | G10: =G6*(1-Hypothèses!$B$10) -> 225 | H10: =H6*(1-Hypothèses!$B$10) -> 315 | I10: =I6*(1-Hypothèses!$B$10) -> 405
A11: COGS TOTAL | B11: k€ | C11: =SUM(C8:C10) -> 127.5 | D11: =SUM(D8:D10) -> 805.52839 | E11: =SUM(E8:E10) -> 2827.9454 | F11: =SUM(F8:F10) -> 6456.0534 | G11: =SUM(G8:G10) -> 12236.103 | H11: =SUM(H8:H10) -> 18438.786 | I11: =SUM(I8:I10) -> 25399.887
A12: MARGE BRUTE | B12: k€ | C12: =C7-C11 -> -7.5 | D12: =D7-D11 -> 524.66086 | E12: =E7-E11 -> 2060.0238 | F12: =F7-F11 -> 5294.3025 | G12: =G7-G11 -> 10917.915 | H12: =H7-H11 -> 18036.455 | I12: =I7-I11 -> 26299.358
A13: Marge brute | B13: % | C13: =C12/C7 -> -0.0625 | D13: =D12/D7 -> 0.39442573 | E13: =E12/E7 -> 0.42144779 | F13: =F12/F7 -> 0.45056529 | G13: =G12/G7 -> 0.47153437 | H13: =H12/H7 -> 0.49448487 | I13: =I12/I7 -> 0.50869907
A14: Masse salariale | B14: k€ | C14: =Hypothèses!C32*Hypothèses!C33/1000 -> 375 | D14: =Hypothèses!D32*Hypothèses!D33/1000 -> 624 | E14: =Hypothèses!E32*Hypothèses!E33/1000 -> 1040 | F14: =Hypothèses!F32*Hypothèses!F33/1000 -> 1804 | G14: =Hypothèses!G32*Hypothèses!G33/1000 -> 2940 | H14: =Hypothèses!H32*Hypothèses!H33/1000 -> 4300 | I14: =Hypothèses!I32*Hypothèses!I33/1000 -> 5720
A15: R&D hors payroll | B15: k€ | C15: =Hypothèses!C34/1000 -> 500 | D15: =Hypothèses!D34/1000 -> 700 | E15: =Hypothèses!E34/1000 -> 800 | F15: =Hypothèses!F34/1000 -> 900 | G15: =Hypothèses!G34/1000 -> 1000 | H15: =Hypothèses!H34/1000 -> 1200 | I15: =Hypothèses!I34/1000 -> 1400
A16: Sales, Marketing & expansion internationale | B16: k€ | C16: =Hypothèses!C35/1000 -> 75 | D16: =Hypothèses!D35/1000 -> 250 | E16: =Hypothèses!E35/1000 -> 600 | F16: =Hypothèses!F35/1000 -> 1100 | G16: =Hypothèses!G35/1000 -> 1800 | H16: =Hypothèses!H35/1000 -> 2600 | I16: =Hypothèses!I35/1000 -> 3400
A17: G&A | B17: k€ | C17: =Hypothèses!C36/1000 -> 150 | D17: =Hypothèses!D36/1000 -> 250 | E17: =Hypothèses!E36/1000 -> 350 | F17: =Hypothèses!F36/1000 -> 500 | G17: =Hypothèses!G36/1000 -> 700 | H17: =Hypothèses!H36/1000 -> 900 | I17: =Hypothèses!I36/1000 -> 1100
A18: OPEX CASH | B18: k€ | C18: =SUM(C14:C17) -> 1100 | D18: =SUM(D14:D17) -> 1824 | E18: =SUM(E14:E17) -> 2790 | F18: =SUM(F14:F17) -> 4304 | G18: =SUM(G14:G17) -> 6440 | H18: =SUM(H14:H17) -> 9000 | I18: =SUM(I14:I17) -> 11620
A19: EBITDA | B19: k€ | C19: =C12-C18 -> -1107.5 | D19: =D12-D18 -> -1299.3391 | E19: =E12-E18 -> -729.97623 | F19: =F12-F18 -> 990.3025 | G19: =G12-G18 -> 4477.9153 | H19: =H12-H18 -> 9036.4551 | I19: =I12-I18 -> 14679.358
A20: Marge EBITDA | B20: % | C20: =C19/C7 -> -9.2291667 | D20: =D19/D7 -> -0.97680773 | E20: =E19/E7 -> -0.14934141 | F20: =F19/F7 -> 0.084278511 | G20: =G19/G7 -> 0.1933969 | H20: =H19/H7 -> 0.24774216 | I20: =I19/I7 -> 0.28393757
A21: Dotations aux amortissements | B21: k€ | C21: =SUM(Hypothèses!C37)/Hypothèses!$B$13/1000 -> 70 | D21: =SUM(Hypothèses!C37,Hypothèses!D37)/Hypothèses!$B$13/1000 -> 160 | E21: =SUM(Hypothèses!C37,Hypothèses!D37,Hypothèses!E37)/Hypothèses!$B$13/1000 -> 280 | F21: =SUM(Hypothèses!C37,Hypothèses!D37,Hypothèses!E37,Hypothèses!F37)/Hypothèses!$B$13/1000 -> 440 | G21: =SUM(Hypothèses!C37,Hypothèses!D37,Hypothèses!E37,Hypothèses!F37,Hypothèses!G37)/Hypothèses!$B$13/1000 -> 640 | H21: =SUM(Hypothèses!D37,Hypothèses!E37,Hypothèses!F37,Hypothèses!G37,Hypothèses!H37)/Hypothèses!$B$13/1000 -> 810 | I21: =SUM(Hypothèses!E37,Hypothèses!F37,Hypothèses!G37,Hypothèses!H37,Hypothèses!I37)/Hypothèses!$B$13/1000 -> 1000
A22: EBIT | B22: k€ | C22: =C19-C21 -> -1177.5 | D22: =D19-D21 -> -1459.3391 | E22: =E19-E21 -> -1009.9762 | F22: =F19-F21 -> 550.3025 | G22: =G19-G21 -> 3837.9153 | H22: =H19-H21 -> 8226.4551 | I22: =I19-I21 -> 13679.358
A23: Résultat financier | B23: k€ | C23: =0 -> 0 | D23: =0 -> 0 | E23: =0 -> 0 | F23: =0 -> 0 | G23: =0 -> 0 | H23: =0 -> 0 | I23: =0 -> 0
A24: Résultat avant impôt | B24: k€ | C24: =C22+C23 -> -1177.5 | D24: =D22+D23 -> -1459.3391 | E24: =E22+E23 -> -1009.9762 | F24: =F22+F23 -> 550.3025 | G24: =G22+G23 -> 3837.9153 | H24: =H22+H23 -> 8226.4551 | I24: =I22+I23 -> 13679.358
A25: Déficits reportables ouverture | B25: k€ | C25: =0 -> 0 | D25: =C28 -> 1177.5 | E25: =D28 -> 2636.8391 | F25: =E28 -> 3646.8154 | G25: =F28 -> 3096.5129 | H25: =G28 -> 0 | I25: =H28 -> 0
A26: Déficits générés | B26: k€ | C26: =MAX(0,-C24) -> 1177.5 | D26: =MAX(0,-D24) -> 1459.3391 | E26: =MAX(0,-E24) -> 1009.9762 | F26: =MAX(0,-F24) -> 0 | G26: =MAX(0,-G24) -> 0 | H26: =MAX(0,-H24) -> 0 | I26: =MAX(0,-I24) -> 0
A27: Déficits utilisés | B27: k€ | C27: =MIN(C25,MAX(0,C24)) -> 0 | D27: =MIN(D25,MAX(0,D24)) -> 0 | E27: =MIN(E25,MAX(0,E24)) -> 0 | F27: =MIN(F25,MAX(0,F24)) -> 550.3025 | G27: =MIN(G25,MAX(0,G24)) -> 3096.5129 | H27: =MIN(H25,MAX(0,H24)) -> 0 | I27: =MIN(I25,MAX(0,I24)) -> 0
A28: Déficits reportables clôture | B28: k€ | C28: =C25+C26-C27 -> 1177.5 | D28: =D25+D26-D27 -> 2636.8391 | E28: =E25+E26-E27 -> 3646.8154 | F28: =F25+F26-F27 -> 3096.5129 | G28: =G25+G26-G27 -> 0 | H28: =H25+H26-H27 -> 0 | I28: =I25+I26-I27 -> 0
A29: Résultat taxable | B29: k€ | C29: =MAX(0,C24-C27) -> 0 | D29: =MAX(0,D24-D27) -> 0 | E29: =MAX(0,E24-E27) -> 0 | F29: =MAX(0,F24-F27) -> 0 | G29: =MAX(0,G24-G27) -> 741.40243 | H29: =MAX(0,H24-H27) -> 8226.4551 | I29: =MAX(0,I24-I27) -> 13679.358
A30: IS | B30: k€ | C30: =C29*Hypothèses!$B$5 -> 0 | D30: =D29*Hypothèses!$B$5 -> 0 | E30: =E29*Hypothèses!$B$5 -> 0 | F30: =F29*Hypothèses!$B$5 -> 0 | G30: =G29*Hypothèses!$B$5 -> 185.35061 | H30: =H29*Hypothèses!$B$5 -> 2056.6138 | I30: =I29*Hypothèses!$B$5 -> 3419.8394
A31: RÉSULTAT NET | B31: k€ | C31: =C24-C30 -> -1177.5 | D31: =D24-D30 -> -1459.3391 | E31: =E24-E30 -> -1009.9762 | F31: =F24-F30 -> 550.3025 | G31: =G24-G30 -> 3652.5647 | H31: =H24-H30 -> 6169.8414 | I31: =I24-I30 -> 10259.518
A32: Marge nette | B32: % | C32: =C31/C7 -> -9.8125 | D32: =D31/D7 -> -1.0970914 | E32: =E31/E7 -> -0.20662492 | F32: =F31/F7 -> 0.046832837 | G32: =G31/G7 -> 0.15775079 | H32: =H31/H7 -> 0.16915149 | I32: =I31/I7 -> 0.19844619

Sheet Cash Flow
A1: SOLAR WRAP — Trésorerie, BFR et besoin de financement
A2: Montants en k€ | le besoin de financement est calculé avant apports externes | B2: Montants en k€ | le besoin de financement est calculé avant apports externes | C2: Montants en k€ | le besoin de financement est calculé avant apports externes | D2: Montants en k€ | le besoin de financement est calculé avant apports externes | E2: Montants en k€ | le besoin de financement est calculé avant apports externes | F2: Montants en k€ | le besoin de financement est calculé avant apports externes | G2: Montants en k€ | le besoin de financement est calculé avant apports externes | H2: Montants en k€ | le besoin de financement est calculé avant apports externes | I2: Montants en k€ | le besoin de financement est calculé avant apports externes
A3: Cash Flow | B3: Unité | C3: 2027 | D3: 2028 | E3: 2029 | F3: 2030 | G3: 2031 | H3: 2032 | I3: 2033
A4: EBITDA | B4: k€ | C4: ='P&L'!C19 -> -1107.5 | D4: ='P&L'!D19 -> -1299.3391 | E4: ='P&L'!E19 -> -729.97623 | F4: ='P&L'!F19 -> 990.3025 | G4: ='P&L'!G19 -> 4477.9153 | H4: ='P&L'!H19 -> 9036.4551 | I4: ='P&L'!I19 -> 14679.358
A5: IS payé | B5: k€ | C5: ='P&L'!C30 -> 0 | D5: ='P&L'!D30 -> 0 | E5: ='P&L'!E30 -> 0 | F5: ='P&L'!F30 -> 0 | G5: ='P&L'!G30 -> 185.35061 | H5: ='P&L'!H30 -> 2056.6138 | I5: ='P&L'!I30 -> 3419.8394
A6: CAPEX | B6: k€ | C6: =Hypothèses!C37/1000 -> 350 | D6: =Hypothèses!D37/1000 -> 450 | E6: =Hypothèses!E37/1000 -> 600 | F6: =Hypothèses!F37/1000 -> 800 | G6: =Hypothèses!G37/1000 -> 1000 | H6: =Hypothèses!H37/1000 -> 1200 | I6: =Hypothèses!I37/1000 -> 1400
A7: Créances clients | B7: k€ | C7: ='P&L'!C7*Hypothèses!$B$6/365 -> 14.794521 | D7: ='P&L'!D7*Hypothèses!$B$6/365 -> 163.99593 | E7: ='P&L'!E7*Hypothèses!$B$6/365 -> 602.62633 | F7: ='P&L'!F7*Hypothèses!$B$6/365 -> 1448.674 | G7: ='P&L'!G7*Hypothèses!$B$6/365 -> 2854.605 | H7: ='P&L'!H7*Hypothèses!$B$6/365 -> 4496.9476 | I7: ='P&L'!I7*Hypothèses!$B$6/365 -> 6373.8795
A8: Stock | B8: k€ | C8: ='P&L'!C8*Hypothèses!$B$7/365 -> 20.958904 | D8: ='P&L'!D8*Hypothèses!$B$7/365 -> 128.21918 | E8: ='P&L'!E8*Hypothèses!$B$7/365 -> 451.23288 | F8: ='P&L'!F8*Hypothèses!$B$7/365 -> 1030.6849 | G8: ='P&L'!G8*Hypothèses!$B$7/365 -> 1952.8767 | H8: ='P&L'!H8*Hypothèses!$B$7/365 -> 2934.2466 | I8: ='P&L'!I8*Hypothèses!$B$7/365 -> 4027.3973
A9: Dettes fournisseurs | B9: k€ | C9: ='P&L'!C11*Hypothèses!$B$8/365 -> 15.719178 | D9: ='P&L'!D11*Hypothèses!$B$8/365 -> 99.311719 | E9: ='P&L'!E11*Hypothèses!$B$8/365 -> 348.6508 | F9: ='P&L'!F11*Hypothèses!$B$8/365 -> 795.95179 | G9: ='P&L'!G11*Hypothèses!$B$8/365 -> 1508.5606 | H9: ='P&L'!H11*Hypothèses!$B$8/365 -> 2273.275 | I9: ='P&L'!I11*Hypothèses!$B$8/365 -> 3131.4929
A10: BFR net | B10: k€ | C10: =C7+C8-C9 -> 20.034247 | D10: =D7+D8-D9 -> 192.90339 | E10: =E7+E8-E9 -> 705.20841 | F10: =F7+F8-F9 -> 1683.4072 | G10: =G7+G8-G9 -> 3298.9211 | H10: =H7+H8-H9 -> 5157.9191 | I10: =I7+I8-I9 -> 7269.7838
A11: Variation BFR | B11: k€ | C11: =C10 -> 20.034247 | D11: =D10-C10 -> 172.86915 | E11: =E10-D10 -> 512.30502 | F11: =F10-E10 -> 978.19875 | G11: =G10-F10 -> 1615.5139 | H11: =H10-G10 -> 1858.9981 | I11: =I10-H10 -> 2111.8647
A12: FREE CASH FLOW AVANT FINANCEMENT | B12: k€ | C12: =C4-C5-C6-C11 -> -1477.5342 | D12: =D4-D5-D6-D11 -> -1922.2083 | E12: =E4-E5-E6-E11 -> -1842.2812 | F12: =F4-F5-F6-F11 -> -787.89625 | G12: =G4-G5-G6-G11 -> 1677.0508 | H12: =H4-H5-H6-H11 -> 3920.8433 | I12: =I4-I5-I6-I11 -> 7747.6536
A13: Trésorerie ouverture | B13: k€ | C13: =Hypothèses!$B$12/1000 -> 250 | D13: =C15 -> 772.46575 | E13: =D15 -> 1350.2575 | F13: =E15 -> 1007.9762 | G13: =F15 -> 220.07997 | H13: =G15 -> 1897.1308 | I13: =H15 -> 5817.9741
A14: Financement externe | B14: k€ | C14: =Hypothèses!C38/1000 -> 2000 | D14: =Hypothèses!D38/1000 -> 2500 | E14: =Hypothèses!E38/1000 -> 1500 | F14: =Hypothèses!F38/1000 -> 0 | G14: =Hypothèses!G38/1000 -> 0 | H14: =Hypothèses!H38/1000 -> 0 | I14: =Hypothèses!I38/1000 -> 0
A15: TRÉSORERIE CLÔTURE | B15: k€ | C15: =C13+C12+C14 -> 772.46575 | D15: =D13+D12+D14 -> 1350.2575 | E15: =E13+E12+E14 -> 1007.9762 | F15: =F13+F12+F14 -> 220.07997 | G15: =G13+G12+G14 -> 1897.1308 | H15: =H13+H12+H14 -> 5817.9741 | I15: =I13+I12+I14 -> 13565.628
A16: Trésorerie avant financement | B16: k€ | C16: =C13+C12 -> -1227.5342 | D16: =C16+D12 -> -3149.7425 | E16: =D16+E12 -> -4992.0238 | F16: =E16+F12 -> -5779.92 | G16: =F16+G12 -> -4102.8692 | H16: =G16+H12 -> -182.02595 | I16: =H16+I12 -> 7565.6277

Sheet Financement
A1: SOLAR WRAP — Plan de financement
A2: Objectif : financer le passage prototype → industrialisation → déploiement sans dépendre d'hypothèses de licences ou subventions non sécurisées | B2: Objectif : financer le passage prototype → industrialisation → déploiement sans dépendre d'hypothèses de licences ou subventions non sécurisées | C2: Objectif : financer le passage prototype → industrialisation → déploiement sans dépendre d'hypothèses de licences ou subventions non sécurisées | D2: Objectif : financer le passage prototype → industrialisation → déploiement sans dépendre d'hypothèses de licences ou subventions non sécurisées | E2: Objectif : financer le passage prototype → industrialisation → déploiement sans dépendre d'hypothèses de licences ou subventions non sécurisées | F2: Objectif : financer le passage prototype → industrialisation → déploiement sans dépendre d'hypothèses de licences ou subventions non sécurisées | G2: Objectif : financer le passage prototype → industrialisation → déploiement sans dépendre d'hypothèses de licences ou subventions non sécurisées | H2: Objectif : financer le passage prototype → industrialisation → déploiement sans dépendre d'hypothèses de licences ou subventions non sécurisées | I2: Objectif : financer le passage prototype → industrialisation → déploiement sans dépendre d'hypothèses de licences ou subventions non sécurisées
A3: A. Besoin de financement | B3: A. Besoin de financement | C3: A. Besoin de financement | D3: A. Besoin de financement | E3: A. Besoin de financement | F3: A. Besoin de financement | G3: A. Besoin de financement | H3: A. Besoin de financement | I3: A. Besoin de financement
A4: Indicateur | B4: Unité | C4: Valeur
A5: Besoin de financement maximal avant apports | B5: k€ | C5: =-MIN('Cash Flow'!C16:I16) -> 5779.92
A6: Enveloppe de financement prévue | B6: k€ | C6: =SUM(Hypothèses!C38:I38)/1000 -> 6000
A7: Marge de sécurité de financement | B7: k€ | C7: =C6-C5 -> 220.07997
A8: Année EBITDA positif | B8: année | C8: =IF('P&L'!C19>=0,2027,IF('P&L'!D19>=0,2028,IF('P&L'!E19>=0,2029,IF('P&L'!F19>=0,2030,IF('P&L'!G19>=0,2031,IF('P&L'!H19>=0,2032,2033)))))) -> 2030
A9: Année FCF positif | B9: année | C9: =IF('Cash Flow'!C12>=0,2027,IF('Cash Flow'!D12>=0,2028,IF('Cash Flow'!E12>=0,2029,IF('Cash Flow'!F12>=0,2030,IF('Cash Flow'!G12>=0,2031,IF('Cash Flow'!H12>=0,2032,2033)))))) -> 2031
A11: B. Tranches proposées dans le modèle | B11: B. Tranches proposées dans le modèle | C11: B. Tranches proposées dans le modèle | D11: B. Tranches proposées dans le modèle | E11: B. Tranches proposées dans le modèle | F11: B. Tranches proposées dans le modèle | G11: B. Tranches proposées dans le modèle | H11: B. Tranches proposées dans le modèle | I11: B. Tranches proposées dans le modèle
A12: Tranche | B12: Nature indicative | C12: 2027 | D12: 2028 | E12: 2029 | F12: 2030 | G12: 2031 | H12: 2032 | I12: 2033
A13: Financement externe | B13: Equity / non dilutif / dette à structurer | C13: =Hypothèses!C38/1000 -> 2000 | D13: =Hypothèses!D38/1000 -> 2500 | E13: =Hypothèses!E38/1000 -> 1500 | F13: =Hypothèses!F38/1000 -> 0 | G13: =Hypothèses!G38/1000 -> 0 | H13: =Hypothèses!H38/1000 -> 0 | I13: =Hypothèses!I38/1000 -> 0
A15: C. Utilisation économique des fonds — lecture COMEX | B15: C. Utilisation économique des fonds — lecture COMEX | C15: C. Utilisation économique des fonds — lecture COMEX | D15: C. Utilisation économique des fonds — lecture COMEX | E15: C. Utilisation économique des fonds — lecture COMEX | F15: C. Utilisation économique des fonds — lecture COMEX | G15: C. Utilisation économique des fonds — lecture COMEX | H15: C. Utilisation économique des fonds — lecture COMEX | I15: C. Utilisation économique des fonds — lecture COMEX
A16: Usage | B16: Période | C16: Rationale
A17: Prototype, validation technique, homologation | B17: 2027–2028 | C17: Priorité n°1 : prouver rendement, durabilité, sécurité et intégration véhicule
A18: Industrialisation / outillage / électronique | B18: 2028–2030 | C18: Construire une architecture industrialisable, avec sous-traitance plutôt qu'une usine lourde
A19: BFR de croissance | B19: 2029–2031 | C19: Financer stock, créances grands comptes et montée en volumes
A20: Commercial / réseau installateurs | B20: 2028–2033 | C20: Accélérer les contrats flotte et la capacité de pose
A21: SOLAR CONTROL / data | B21: 2027–2033 | C21: Créer la couche logicielle différenciante et le revenu récurrent

Sheet Scénarios
A1: SOLAR WRAP — Scénarios Downside / Base / Upside
A2: Les scénarios modifient volumes, prix, coût unitaire, OPEX et CAPEX ; aucun revenu OEM/licence n'est ajouté | B2: Les scénarios modifient volumes, prix, coût unitaire, OPEX et CAPEX ; aucun revenu OEM/licence n'est ajouté | C2: Les scénarios modifient volumes, prix, coût unitaire, OPEX et CAPEX ; aucun revenu OEM/licence n'est ajouté | D2: Les scénarios modifient volumes, prix, coût unitaire, OPEX et CAPEX ; aucun revenu OEM/licence n'est ajouté | E2: Les scénarios modifient volumes, prix, coût unitaire, OPEX et CAPEX ; aucun revenu OEM/licence n'est ajouté | F2: Les scénarios modifient volumes, prix, coût unitaire, OPEX et CAPEX ; aucun revenu OEM/licence n'est ajouté | G2: Les scénarios modifient volumes, prix, coût unitaire, OPEX et CAPEX ; aucun revenu OEM/licence n'est ajouté | H2: Les scénarios modifient volumes, prix, coût unitaire, OPEX et CAPEX ; aucun revenu OEM/licence n'est ajouté | I2: Les scénarios modifient volumes, prix, coût unitaire, OPEX et CAPEX ; aucun revenu OEM/licence n'est ajouté
A3: Scénario | B3: Volume | C3: Prix | D3: COGS / unité | E3: OPEX fixe | F3: CAPEX
A4: Downside | B4: 0.7 | C4: 0.95 | D4: 1.07 | E4: 0.9 | F4: 0.85
A5: Base | B5: 1 | C5: 1 | D5: 1 | E5: 1 | F5: 1
A6: Upside | B6: 1.3 | C6: 1.02 | D6: 0.95 | E6: 1.15 | F6: 1.15
A8: Synthèse | B8: Synthèse | C8: Synthèse | D8: Synthèse | E8: Synthèse | F8: Synthèse | G8: Synthèse | H8: Synthèse | I8: Synthèse
A9: Scénario | B9: CA 2030 (M€) | C9: CA 2033 (M€) | D9: Marge EBITDA 2033 | E9: Break-even EBITDA | F9: Besoin max financement (M€)
A10: Downside | B10: =F15/1000 -> 7.8363991 | C10: =I15/1000 -> 34.526971 | D10: =I19 -> 0.147379 | E10: =IF(C18>=0,2027,IF(D18>=0,2028,IF(E18>=0,2029,IF(F18>=0,2030,IF(G18>=0,2031,IF(H18>=0,2032,2033)))))) -> 2031 | F10: =-MIN(0,MIN(C24:I24))/1000 -> 8.7988011
A11: Base | B11: =F33/1000 -> 11.750356 | C11: =I33/1000 -> 51.699244 | D11: =I37 -> 0.28393757 | E11: =IF(C36>=0,2027,IF(D36>=0,2028,IF(E36>=0,2029,IF(F36>=0,2030,IF(G36>=0,2031,IF(H36>=0,2032,2033)))))) -> 2030 | F11: =-MIN(0,MIN(C42:I42))/1000 -> 5.77992
A12: Upside | B12: =F51/1000 -> 15.564323 | C12: =I51/1000 -> 68.444018 | D12: =I55 -> 0.34559142 | E12: =IF(C54>=0,2027,IF(D54>=0,2028,IF(E54>=0,2029,IF(F54>=0,2030,IF(G54>=0,2031,IF(H54>=0,2032,2033)))))) -> 2030 | F12: =-MIN(0,MIN(C60:I60))/1000 -> 5.1112533 | G12: Downside — trajectoire | H12: Downside — trajectoire | I12: Downside — trajectoire
A13: Indicateur | B13: Unité | C13: 2027 | D13: 2028 | E13: 2029 | F13: 2030 | G13: 2031 | H13: 2032 | I13: 2033
A14: Unités | B14: véhicules | C14: =Ventes!C7*$B$4 -> 10.5 | D14: =Ventes!D7*$B$4 -> 84 | E14: =Ventes!E7*$B$4 -> 315 | F14: =Ventes!F7*$B$4 -> 770 | G14: =Ventes!G7*$B$4 -> 1540 | H14: =Ventes!H7*$B$4 -> 2450 | I14: =Ventes!I7*$B$4 -> 3500
A15: CA | B15: k€ | C15: =((Ventes!C9*$B$4*$C$4)+(Ventes!C16*$B$4)+(Ventes!C17*$B$4))/1000 -> 79.8 | D15: =((Ventes!D9*$B$4*$C$4)+(Ventes!D16*$B$4)+(Ventes!D17*$B$4))/1000 -> 887.03247 | E15: =((Ventes!E9*$B$4*$C$4)+(Ventes!E16*$B$4)+(Ventes!E17*$B$4))/1000 -> 3259.3534 | F15: =((Ventes!F9*$B$4*$C$4)+(Ventes!F16*$B$4)+(Ventes!F17*$B$4))/1000 -> 7836.3991 | G15: =((Ventes!G9*$B$4*$C$4)+(Ventes!G16*$B$4)+(Ventes!G17*$B$4))/1000 -> 15445.513 | H15: =((Ventes!H9*$B$4*$C$4)+(Ventes!H16*$B$4)+(Ventes!H17*$B$4))/1000 -> 24344.419 | I15: =((Ventes!I9*$B$4*$C$4)+(Ventes!I16*$B$4)+(Ventes!I17*$B$4))/1000 -> 34526.971
A16: Marge brute | B16: k€ | C16: =(((Ventes!C9*$B$4*$C$4)-(Ventes!C7*Hypothèses!C28*$B$4*$D$4))+(Ventes!C16*$B$4*Hypothèses!$B$11)+(Ventes!C17*$B$4*Hypothèses!$B$10))/1000 -> -15.6975 | D16: =(((Ventes!D9*$B$4*$C$4)-(Ventes!D7*Hypothèses!D28*$B$4*$D$4))+(Ventes!D16*$B$4*Hypothèses!$B$11)+(Ventes!D17*$B$4*Hypothèses!$B$10))/1000 -> 284.9426 | E16: =(((Ventes!E9*$B$4*$C$4)-(Ventes!E7*Hypothèses!E28*$B$4*$D$4))+(Ventes!E16*$B$4*Hypothèses!$B$11)+(Ventes!E17*$B$4*Hypothèses!$B$10))/1000 -> 1145.2866 | F16: =(((Ventes!F9*$B$4*$C$4)-(Ventes!F7*Hypothèses!F28*$B$4*$D$4))+(Ventes!F16*$B$4*Hypothèses!$B$11)+(Ventes!F17*$B$4*Hypothèses!$B$10))/1000 -> 3009.9317 | G16: =(((Ventes!G9*$B$4*$C$4)-(Ventes!G7*Hypothèses!G28*$B$4*$D$4))+(Ventes!G16*$B$4*Hypothèses!$B$11)+(Ventes!G17*$B$4*Hypothèses!$B$10))/1000 -> 6298.1207 | H16: =(((Ventes!H9*$B$4*$C$4)-(Ventes!H7*Hypothèses!H28*$B$4*$D$4))+(Ventes!H16*$B$4*Hypothèses!$B$11)+(Ventes!H17*$B$4*Hypothèses!$B$10))/1000 -> 10562.619 | I16: =(((Ventes!I9*$B$4*$C$4)-(Ventes!I7*Hypothèses!I28*$B$4*$D$4))+(Ventes!I16*$B$4*Hypothèses!$B$11)+(Ventes!I17*$B$4*Hypothèses!$B$10))/1000 -> 15546.55
A17: OPEX fixe | B17: k€ | C17: ='P&L'!C18*$E$4 -> 990 | D17: ='P&L'!D18*$E$4 -> 1641.6 | E17: ='P&L'!E18*$E$4 -> 2511 | F17: ='P&L'!F18*$E$4 -> 3873.6 | G17: ='P&L'!G18*$E$4 -> 5796 | H17: ='P&L'!H18*$E$4 -> 8100 | I17: ='P&L'!I18*$E$4 -> 10458
A18: EBITDA | B18: k€ | C18: =C16-C17 -> -1005.6975 | D18: =D16-D17 -> -1356.6574 | E18: =E16-E17 -> -1365.7134 | F18: =F16-F17 -> -863.66825 | G18: =G16-G17 -> 502.12071 | H18: =H16-H17 -> 2462.6186 | I18: =I16-I17 -> 5088.5504
A19: Marge EBITDA | B19: % | C19: =C18/C15 -> -12.602726 | D19: =D18/D15 -> -1.5294337 | E19: =E18/E15 -> -0.41901359 | F19: =F18/F15 -> -0.11021239 | G19: =G18/G15 -> 0.032509164 | H19: =H18/H15 -> 0.10115742 | I19: =I18/I15 -> 0.147379
A20: BFR | B20: k€ | C20: =(C15*Hypothèses!$B$6/365)+((Ventes!C7*Hypothèses!C28*$B$4*$D$4/1000)*Hypothèses!$B$7/365)-(((C15-C16)*Hypothèses!$B$8/365)) -> 13.762911 | D20: =(D15*Hypothèses!$B$6/365)+((Ventes!D7*Hypothèses!D28*$B$4*$D$4/1000)*Hypothèses!$B$7/365)-(((D15-D16)*Hypothèses!$B$8/365)) -> 131.16607 | E20: =(E15*Hypothèses!$B$6/365)+((Ventes!E7*Hypothèses!E28*$B$4*$D$4/1000)*Hypothèses!$B$7/365)-(((E15-E16)*Hypothèses!$B$8/365)) -> 479.17315 | F20: =(F15*Hypothèses!$B$6/365)+((Ventes!F7*Hypothèses!F28*$B$4*$D$4/1000)*Hypothèses!$B$7/365)-(((F15-F16)*Hypothèses!$B$8/365)) -> 1143.0705 | G20: =(G15*Hypothèses!$B$6/365)+((Ventes!G7*Hypothèses!G28*$B$4*$D$4/1000)*Hypothèses!$B$7/365)-(((G15-G16)*Hypothèses!$B$8/365)) -> 2239.1853 | H20: =(H15*Hypothèses!$B$6/365)+((Ventes!H7*Hypothèses!H28*$B$4*$D$4/1000)*Hypothèses!$B$7/365)-(((H15-H16)*Hypothèses!$B$8/365)) -> 3499.9913 | I20: =(I15*Hypothèses!$B$6/365)+((Ventes!I7*Hypothèses!I28*$B$4*$D$4/1000)*Hypothèses!$B$7/365)-(((I15-I16)*Hypothèses!$B$8/365)) -> 4933.2185
A21: Variation BFR | B21: k€ | C21: =C20 -> 13.762911 | D21: =D20-C20 -> 117.40316 | E21: =E20-D20 -> 348.00707 | F21: =F20-E20 -> 663.89734 | G21: =G20-F20 -> 1096.1148 | H21: =H20-G20 -> 1260.806 | I21: =I20-H20 -> 1433.2272
A22: CAPEX | B22: k€ | C22: =Hypothèses!C37*$F$4/1000 -> 297.5 | D22: =Hypothèses!D37*$F$4/1000 -> 382.5 | E22: =Hypothèses!E37*$F$4/1000 -> 510 | F22: =Hypothèses!F37*$F$4/1000 -> 680 | G22: =Hypothèses!G37*$F$4/1000 -> 850 | H22: =Hypothèses!H37*$F$4/1000 -> 1020 | I22: =Hypothèses!I37*$F$4/1000 -> 1190
A23: FCF avant financement | B23: k€ | C23: =C18-C21-C22 -> -1316.9604 | D23: =D18-D21-D22 -> -1856.5606 | E23: =E18-E21-E22 -> -2223.7204 | F23: =F18-F21-F22 -> -2207.5656 | G23: =G18-G21-G22 -> -1443.9941 | H23: =H18-H21-H22 -> 181.81256 | I23: =I18-I21-I22 -> 2465.3232
A24: Cash cumulé sans financement | B24: k€ | C24: =Hypothèses!$B$12/1000+C23 -> -1066.9604 | D24: =C24+D23 -> -2923.521 | E24: =D24+E23 -> -5147.2414 | F24: =E24+F23 -> -7354.807 | G24: =F24+G23 -> -8798.8011 | H24: =G24+H23 -> -8616.9885 | I24: =H24+I23 -> -6151.6653
A30: Base — trajectoire | B30: Base — trajectoire | C30: Base — trajectoire | D30: Base — trajectoire | E30: Base — trajectoire | F30: Base — trajectoire | G30: Base — trajectoire | H30: Base — trajectoire | I30: Base — trajectoire
A31: Indicateur | B31: Unité | C31: 2027 | D31: 2028 | E31: 2029 | F31: 2030 | G31: 2031 | H31: 2032 | I31: 2033
A32: Unités | B32: véhicules | C32: =Ventes!C7*$B$5 -> 15 | D32: =Ventes!D7*$B$5 -> 120 | E32: =Ventes!E7*$B$5 -> 450 | F32: =Ventes!F7*$B$5 -> 1100 | G32: =Ventes!G7*$B$5 -> 2200 | H32: =Ventes!H7*$B$5 -> 3500 | I32: =Ventes!I7*$B$5 -> 5000
A33: CA | B33: k€ | C33: =((Ventes!C9*$B$5*$C$5)+(Ventes!C16*$B$5)+(Ventes!C17*$B$5))/1000 -> 120 | D33: =((Ventes!D9*$B$5*$C$5)+(Ventes!D16*$B$5)+(Ventes!D17*$B$5))/1000 -> 1330.1892 | E33: =((Ventes!E9*$B$5*$C$5)+(Ventes!E16*$B$5)+(Ventes!E17*$B$5))/1000 -> 4887.9691 | F33: =((Ventes!F9*$B$5*$C$5)+(Ventes!F16*$B$5)+(Ventes!F17*$B$5))/1000 -> 11750.356 | G33: =((Ventes!G9*$B$5*$C$5)+(Ventes!G16*$B$5)+(Ventes!G17*$B$5))/1000 -> 23154.018 | H33: =((Ventes!H9*$B$5*$C$5)+(Ventes!H16*$B$5)+(Ventes!H17*$B$5))/1000 -> 36475.241 | I33: =((Ventes!I9*$B$5*$C$5)+(Ventes!I16*$B$5)+(Ventes!I17*$B$5))/1000 -> 51699.244
A34: Marge brute | B34: k€ | C34: =(((Ventes!C9*$B$5*$C$5)-(Ventes!C7*Hypothèses!C28*$B$5*$D$5))+(Ventes!C16*$B$5*Hypothèses!$B$11)+(Ventes!C17*$B$5*Hypothèses!$B$10))/1000 -> -7.5 | D34: =(((Ventes!D9*$B$5*$C$5)-(Ventes!D7*Hypothèses!D28*$B$5*$D$5))+(Ventes!D16*$B$5*Hypothèses!$B$11)+(Ventes!D17*$B$5*Hypothèses!$B$10))/1000 -> 524.66086 | E34: =(((Ventes!E9*$B$5*$C$5)-(Ventes!E7*Hypothèses!E28*$B$5*$D$5))+(Ventes!E16*$B$5*Hypothèses!$B$11)+(Ventes!E17*$B$5*Hypothèses!$B$10))/1000 -> 2060.0238 | F34: =(((Ventes!F9*$B$5*$C$5)-(Ventes!F7*Hypothèses!F28*$B$5*$D$5))+(Ventes!F16*$B$5*Hypothèses!$B$11)+(Ventes!F17*$B$5*Hypothèses!$B$10))/1000 -> 5294.3025 | G34: =(((Ventes!G9*$B$5*$C$5)-(Ventes!G7*Hypothèses!G28*$B$5*$D$5))+(Ventes!G16*$B$5*Hypothèses!$B$11)+(Ventes!G17*$B$5*Hypothèses!$B$10))/1000 -> 10917.915 | H34: =(((Ventes!H9*$B$5*$C$5)-(Ventes!H7*Hypothèses!H28*$B$5*$D$5))+(Ventes!H16*$B$5*Hypothèses!$B$11)+(Ventes!H17*$B$5*Hypothèses!$B$10))/1000 -> 18036.455 | I34: =(((Ventes!I9*$B$5*$C$5)-(Ventes!I7*Hypothèses!I28*$B$5*$D$5))+(Ventes!I16*$B$5*Hypothèses!$B$11)+(Ventes!I17*$B$5*Hypothèses!$B$10))/1000 -> 26299.358
A35: OPEX fixe | B35: k€ | C35: ='P&L'!C18*$E$5 -> 1100 | D35: ='P&L'!D18*$E$5 -> 1824 | E35: ='P&L'!E18*$E$5 -> 2790 | F35: ='P&L'!F18*$E$5 -> 4304 | G35: ='P&L'!G18*$E$5 -> 6440 | H35: ='P&L'!H18*$E$5 -> 9000 | I35: ='P&L'!I18*$E$5 -> 11620
A36: EBITDA | B36: k€ | C36: =C34-C35 -> -1107.5 | D36: =D34-D35 -> -1299.3391 | E36: =E34-E35 -> -729.97623 | F36: =F34-F35 -> 990.3025 | G36: =G34-G35 -> 4477.9153 | H36: =H34-H35 -> 9036.4551 | I36: =I34-I35 -> 14679.358
A37: Marge EBITDA | B37: % | C37: =C36/C33 -> -9.2291667 | D37: =D36/D33 -> -0.97680773 | E37: =E36/E33 -> -0.14934141 | F37: =F36/F33 -> 0.084278511 | G37: =G36/G33 -> 0.1933969 | H37: =H36/H33 -> 0.24774216 | I37: =I36/I33 -> 0.28393757
A38: BFR | B38: k€ | C38: =(C33*Hypothèses!$B$6/365)+((Ventes!C7*Hypothèses!C28*$B$5*$D$5/1000)*Hypothèses!$B$7/365)-(((C33-C34)*Hypothèses!$B$8/365)) -> 20.034247 | D38: =(D33*Hypothèses!$B$6/365)+((Ventes!D7*Hypothèses!D28*$B$5*$D$5/1000)*Hypothèses!$B$7/365)-(((D33-D34)*Hypothèses!$B$8/365)) -> 192.90339 | E38: =(E33*Hypothèses!$B$6/365)+((Ventes!E7*Hypothèses!E28*$B$5*$D$5/1000)*Hypothèses!$B$7/365)-(((E33-E34)*Hypothèses!$B$8/365)) -> 705.20841 | F38: =(F33*Hypothèses!$B$6/365)+((Ventes!F7*Hypothèses!F28*$B$5*$D$5/1000)*Hypothèses!$B$7/365)-(((F33-F34)*Hypothèses!$B$8/365)) -> 1683.4072 | G38: =(G33*Hypothèses!$B$6/365)+((Ventes!G7*Hypothèses!G28*$B$5*$D$5/1000)*Hypothèses!$B$7/365)-(((G33-G34)*Hypothèses!$B$8/365)) -> 3298.9211 | H38: =(H33*Hypothèses!$B$6/365)+((Ventes!H7*Hypothèses!H28*$B$5*$D$5/1000)*Hypothèses!$B$7/365)-(((H33-H34)*Hypothèses!$B$8/365)) -> 5157.9191 | I38: =(I33*Hypothèses!$B$6/365)+((Ventes!I7*Hypothèses!I28*$B$5*$D$5/1000)*Hypothèses!$B$7/365)-(((I33-I34)*Hypothèses!$B$8/365)) -> 7269.7838
A39: Variation BFR | B39: k€ | C39: =C38 -> 20.034247 | D39: =D38-C38 -> 172.86915 | E39: =E38-D38 -> 512.30502 | F39: =F38-E38 -> 978.19875 | G39: =G38-F38 -> 1615.5139 | H39: =H38-G38 -> 1858.9981 | I39: =I38-H38 -> 2111.8647
A40: CAPEX | B40: k€ | C40: =Hypothèses!C37*$F$5/1000 -> 350 | D40: =Hypothèses!D37*$F$5/1000 -> 450 | E40: =Hypothèses!E37*$F$5/1000 -> 600 | F40: =Hypothèses!F37*$F$5/1000 -> 800 | G40: =Hypothèses!G37*$F$5/1000 -> 1000 | H40: =Hypothèses!H37*$F$5/1000 -> 1200 | I40: =Hypothèses!I37*$F$5/1000 -> 1400
A41: FCF avant financement | B41: k€ | C41: =C36-C39-C40 -> -1477.5342 | D41: =D36-D39-D40 -> -1922.2083 | E41: =E36-E39-E40 -> -1842.2812 | F41: =F36-F39-F40 -> -787.89625 | G41: =G36-G39-G40 -> 1862.4014 | H41: =H36-H39-H40 -> 5977.4571 | I41: =I36-I39-I40 -> 11167.493
A42: Cash cumulé sans financement | B42: k€ | C42: =Hypothèses!$B$12/1000+C41 -> -1227.5342 | D42: =C42+D41 -> -3149.7425 | E42: =D42+E41 -> -4992.0238 | F42: =E42+F41 -> -5779.92 | G42: =F42+G41 -> -3917.5186 | H42: =G42+H41 -> 2059.9384 | I42: =H42+I41 -> 13227.432
A48: Upside — trajectoire | B48: Upside — trajectoire | C48: Upside — trajectoire | D48: Upside — trajectoire | E48: Upside — trajectoire | F48: Upside — trajectoire | G48: Upside — trajectoire | H48: Upside — trajectoire | I48: Upside — trajectoire
A49: Indicateur | B49: Unité | C49: 2027 | D49: 2028 | E49: 2029 | F49: 2030 | G49: 2031 | H49: 2032 | I49: 2033
A50: Unités | B50: véhicules | C50: =Ventes!C7*$B$6 -> 19.5 | D50: =Ventes!D7*$B$6 -> 156 | E50: =Ventes!E7*$B$6 -> 585 | F50: =Ventes!F7*$B$6 -> 1430 | G50: =Ventes!G7*$B$6 -> 2860 | H50: =Ventes!H7*$B$6 -> 4550 | I50: =Ventes!I7*$B$6 -> 6500
A51: CA | B51: k€ | C51: =((Ventes!C9*$B$6*$C$6)+(Ventes!C16*$B$6)+(Ventes!C17*$B$6))/1000 -> 159.12 | D51: =((Ventes!D9*$B$6*$C$6)+(Ventes!D16*$B$6)+(Ventes!D17*$B$6))/1000 -> 1762.006 | E51: =((Ventes!E9*$B$6*$C$6)+(Ventes!E16*$B$6)+(Ventes!E17*$B$6))/1000 -> 6474.8699 | F51: =((Ventes!F9*$B$6*$C$6)+(Ventes!F16*$B$6)+(Ventes!F17*$B$6))/1000 -> 15564.323 | G51: =((Ventes!G9*$B$6*$C$6)+(Ventes!G16*$B$6)+(Ventes!G17*$B$6))/1000 -> 30666.503 | H51: =((Ventes!H9*$B$6*$C$6)+(Ventes!H16*$B$6)+(Ventes!H17*$B$6))/1000 -> 48300.514 | I51: =((Ventes!I9*$B$6*$C$6)+(Ventes!I16*$B$6)+(Ventes!I17*$B$6))/1000 -> 68444.018
...

Sheet Sensibilité
A1: SOLAR WRAP — Sensibilité EBITDA 2030
A2: Sensibilité à la marge brute hardware et au volume de ventes ; montants en M€ | B2: Sensibilité à la marge brute hardware et au volume de ventes ; montants en M€ | C2: Sensibilité à la marge brute hardware et au volume de ventes ; montants en M€ | D2: Sensibilité à la marge brute hardware et au volume de ventes ; montants en M€ | E2: Sensibilité à la marge brute hardware et au volume de ventes ; montants en M€ | F2: Sensibilité à la marge brute hardware et au volume de ventes ; montants en M€ | G2: Sensibilité à la marge brute hardware et au volume de ventes ; montants en M€ | H2: Sensibilité à la marge brute hardware et au volume de ventes ; montants en M€ | I2: Sensibilité à la marge brute hardware et au volume de ventes ; montants en M€
A3: EBITDA 2030 selon volume et marge brute hardware | B3: EBITDA 2030 selon volume et marge brute hardware | C3: EBITDA 2030 selon volume et marge brute hardware | D3: EBITDA 2030 selon volume et marge brute hardware | E3: EBITDA 2030 selon volume et marge brute hardware | F3: EBITDA 2030 selon volume et marge brute hardware | G3: EBITDA 2030 selon volume et marge brute hardware | H3: EBITDA 2030 selon volume et marge brute hardware | I3: EBITDA 2030 selon volume et marge brute hardware
A4: Volume vs base | B4: Unités 2030 | C4: 0.35 | D4: 0.4 | E4: 0.45 | F4: 0.5 | G4: 0.55
A5: 0.8 | B5: =Ventes!F7*A5 -> 880 | C5: =((B5*Hypothèses!F27*C$4)+('P&L'!F5*1000*Hypothèses!$B$11*A5)+('P&L'!F6*1000*Hypothèses!$B$10*A5)-('P&L'!F18*1000))/1000000 -> -0.829758 | D5: =((B5*Hypothèses!F27*D$4)+('P&L'!F5*1000*Hypothèses!$B$11*A5)+('P&L'!F6*1000*Hypothèses!$B$10*A5)-('P&L'!F18*1000))/1000000 -> -0.385358 | E5: =((B5*Hypothèses!F27*E$4)+('P&L'!F5*1000*Hypothèses!$B$11*A5)+('P&L'!F6*1000*Hypothèses!$B$10*A5)-('P&L'!F18*1000))/1000000 -> 0.059041998 | F5: =((B5*Hypothèses!F27*F$4)+('P&L'!F5*1000*Hypothèses!$B$11*A5)+('P&L'!F6*1000*Hypothèses!$B$10*A5)-('P&L'!F18*1000))/1000000 -> 0.503442 | G5: =((B5*Hypothèses!F27*G$4)+('P&L'!F5*1000*Hypothèses!$B$11*A5)+('P&L'!F6*1000*Hypothèses!$B$10*A5)-('P&L'!F18*1000))/1000000 -> 0.947842
A6: 0.9 | B6: =Ventes!F7*A6 -> 990 | C6: =((B6*Hypothèses!F27*C$4)+('P&L'!F5*1000*Hypothèses!$B$11*A6)+('P&L'!F6*1000*Hypothèses!$B$10*A6)-('P&L'!F18*1000))/1000000 -> -0.39547775 | D6: =((B6*Hypothèses!F27*D$4)+('P&L'!F5*1000*Hypothèses!$B$11*A6)+('P&L'!F6*1000*Hypothèses!$B$10*A6)-('P&L'!F18*1000))/1000000 -> 0.10447225 | E6: =((B6*Hypothèses!F27*E$4)+('P&L'!F5*1000*Hypothèses!$B$11*A6)+('P&L'!F6*1000*Hypothèses!$B$10*A6)-('P&L'!F18*1000))/1000000 -> 0.60442225 | F6: =((B6*Hypothèses!F27*F$4)+('P&L'!F5*1000*Hypothèses!$B$11*A6)+('P&L'!F6*1000*Hypothèses!$B$10*A6)-('P&L'!F18*1000))/1000000 -> 1.1043722 | G6: =((B6*Hypothèses!F27*G$4)+('P&L'!F5*1000*Hypothèses!$B$11*A6)+('P&L'!F6*1000*Hypothèses!$B$10*A6)-('P&L'!F18*1000))/1000000 -> 1.6043222
A7: 1 | B7: =Ventes!F7*A7 -> 1100 | C7: =((B7*Hypothèses!F27*C$4)+('P&L'!F5*1000*Hypothèses!$B$11*A7)+('P&L'!F6*1000*Hypothèses!$B$10*A7)-('P&L'!F18*1000))/1000000 -> 0.038802497 | D7: =((B7*Hypothèses!F27*D$4)+('P&L'!F5*1000*Hypothèses!$B$11*A7)+('P&L'!F6*1000*Hypothèses!$B$10*A7)-('P&L'!F18*1000))/1000000 -> 0.5943025 | E7: =((B7*Hypothèses!F27*E$4)+('P&L'!F5*1000*Hypothèses!$B$11*A7)+('P&L'!F6*1000*Hypothèses!$B$10*A7)-('P&L'!F18*1000))/1000000 -> 1.1498025 | F7: =((B7*Hypothèses!F27*F$4)+('P&L'!F5*1000*Hypothèses!$B$11*A7)+('P&L'!F6*1000*Hypothèses!$B$10*A7)-('P&L'!F18*1000))/1000000 -> 1.7053025 | G7: =((B7*Hypothèses!F27*G$4)+('P&L'!F5*1000*Hypothèses!$B$11*A7)+('P&L'!F6*1000*Hypothèses!$B$10*A7)-('P&L'!F18*1000))/1000000 -> 2.2608025
A8: 1.1 | B8: =Ventes!F7*A8 -> 1210 | C8: =((B8*Hypothèses!F27*C$4)+('P&L'!F5*1000*Hypothèses!$B$11*A8)+('P&L'!F6*1000*Hypothèses!$B$10*A8)-('P&L'!F18*1000))/1000000 -> 0.47308275 | D8: =((B8*Hypothèses!F27*D$4)+('P&L'!F5*1000*Hypothèses!$B$11*A8)+('P&L'!F6*1000*Hypothèses!$B$10*A8)-('P&L'!F18*1000))/1000000 -> 1.0841327 | E8: =((B8*Hypothèses!F27*E$4)+('P&L'!F5*1000*Hypothèses!$B$11*A8)+('P&L'!F6*1000*Hypothèses!$B$10*A8)-('P&L'!F18*1000))/1000000 -> 1.6951827 | F8: =((B8*Hypothèses!F27*F$4)+('P&L'!F5*1000*Hypothèses!$B$11*A8)+('P&L'!F6*1000*Hypothèses!$B$10*A8)-('P&L'!F18*1000))/1000000 -> 2.3062327 | G8: =((B8*Hypothèses!F27*G$4)+('P&L'!F5*1000*Hypothèses!$B$11*A8)+('P&L'!F6*1000*Hypothèses!$B$10*A8)-('P&L'!F18*1000))/1000000 -> 2.9172827
A9: 1.2 | B9: =Ventes!F7*A9 -> 1320 | C9: =((B9*Hypothèses!F27*C$4)+('P&L'!F5*1000*Hypothèses!$B$11*A9)+('P&L'!F6*1000*Hypothèses!$B$10*A9)-('P&L'!F18*1000))/1000000 -> 0.907363 | D9: =((B9*Hypothèses!F27*D$4)+('P&L'!F5*1000*Hypothèses!$B$11*A9)+('P&L'!F6*1000*Hypothèses!$B$10*A9)-('P&L'!F18*1000))/1000000 -> 1.573963 | E9: =((B9*Hypothèses!F27*E$4)+('P&L'!F5*1000*Hypothèses!$B$11*A9)+('P&L'!F6*1000*Hypothèses!$B$10*A9)-('P&L'!F18*1000))/1000000 -> 2.240563 | F9: =((B9*Hypothèses!F27*F$4)+('P&L'!F5*1000*Hypothèses!$B$11*A9)+('P&L'!F6*1000*Hypothèses!$B$10*A9)-('P&L'!F18*1000))/1000000 -> 2.907163 | G9: =((B9*Hypothèses!F27*G$4)+('P&L'!F5*1000*Hypothèses!$B$11*A9)+('P&L'!F6*1000*Hypothèses!$B$10*A9)-('P&L'!F18*1000))/1000000 -> 3.573763

Sheet Sources
A1: SOLAR WRAP — Sources, marché et niveau de preuve
A2: Les données externes soutiennent le cas d'usage ; les coûts, prix et volumes SOLAR WRAP restent des hypothèses management à valider | B2: Les données externes soutiennent le cas d'usage ; les coûts, prix et volumes SOLAR WRAP restent des hypothèses management à valider | C2: Les données externes soutiennent le cas d'usage ; les coûts, prix et volumes SOLAR WRAP restent des hypothèses management à valider | D2: Les données externes soutiennent le cas d'usage ; les coûts, prix et volumes SOLAR WRAP restent des hypothèses management à valider | E2: Les données externes soutiennent le cas d'usage ; les coûts, prix et volumes SOLAR WRAP restent des hypothèses management à valider | F2: Les données externes soutiennent le cas d'usage ; les coûts, prix et volumes SOLAR WRAP restent des hypothèses management à valider | G2: Les données externes soutiennent le cas d'usage ; les coûts, prix et volumes SOLAR WRAP restent des hypothèses management à valider | H2: Les données externes soutiennent le cas d'usage ; les coûts, prix et volumes SOLAR WRAP restent des hypothèses management à valider | I2: Les données externes soutiennent le cas d'usage ; les coûts, prix et volumes SOLAR WRAP restent des hypothèses management à valider
A3: Sujet | B3: Donnée utilisée | C3: Source | D3: URL | E3: Utilisation dans le modèle
A4: VIPV poids lourds / remorques | B4: Jusqu'à 55 kWh/j été sur toit; 90–110 kWh/j avec flancs; cas de payback <2 ans diesel selon simulation | C4: Fraunhofer ISE / SolarMoves 2026 | D4: https://www.ise.fraunhofer.de/content/dam/ise/en/documents/press-releases/2026/1426_ISE_e_PR_Solar-cells-on-vehicles-can-take-the-pressure-off-the-grid-in-Europe.pdf | E4: Validation du cas d'usage logistique; non utilisé comme revenu direct
A5: Économie diesel camion 40 t | B5: 1 500–2 100 L/an dans une campagne Fraunhofer historique | C5: Fraunhofer ISE | D5: https://www.ise.fraunhofer.de/content/dam/ise/en/documents/information-material/brochures/23_en_ISE_Flyer_Solar_modules_integrated_in_trucks_and_vans.pdf | E5: Le modèle retient le bas de fourchette: 1 500 L/an
A6: Remorque frigorifique | B6: Sono annonce >4,5 kWp et ROI 3–5 ans selon usage | C6: Sono Motors | D6: https://ir.sonomotors.com/news-releases/news-release-details/sono-group-nv-accelerates-commercial-rollout-solar-technology/ | E6: Benchmark de faisabilité commerciale / ROI
A7: Bus | B7: Jusqu'à 1 250 L diesel ou 2,1 MWh par bus/an (claim fournisseur) | C7: Sono Motors | D7: https://sonomotors.com/site/assets/files/8669/sono_motors_solar_bus_kit_info_sheet_en-1.pdf | E7: Marché secondaire; non inclus dans l'économie client de base
A8: Prix électricité entreprises | B8: France / UE: ordre de grandeur ~0,16 €/kWh pour certains consommateurs non ménagers en 2026-S1 | C8: Eurostat | D8: https://ec.europa.eu/eurostat/databrowser/view/NRG_PC_205/default/table?category=nrg.nrg_price.nrg_pc&lang=en | E8: Benchmark seulement; le ROI client de base est centré gazole
A9: Prix gazole France | B9: Moyenne 2025: 1,62 €/L TTC; forte volatilité en 2026 | C9: SDES / Ministère transition écologique | D9: https://www.statistiques.developpement-durable.gouv.fr/media/9426/download?inline= | E9: Le modèle retient 1,50 €/L, volontairement prudent et normalisé
A10: Facteur émission gazole | B10: Ordre de grandeur ~3,1 kgCO2e/L amont + combustion | C10: ADEME / Base Empreinte (repris par sources publiques) | D10: https://base-empreinte.ademe.fr/ | E10: Calcul CO2e évité
A11: Impôt sur les sociétés | B11: Taux normal 25% | C11: Service-Public / DILA | D11: https://entreprendre.service-public.gouv.fr/vosdroits/F23575 | E11: Calcul IS après utilisation des déficits reportables
A12: Marché camions électriques | B12: >400 000 ventes mondiales en 2025; 9% des ventes de camions | C12: IEA Global EV Outlook 2026 | D12: https://www.iea.org/reports/global-ev-outlook-2026/trends-in-other-ev-modes | E12: TAM marché professionnel
A13: Marché utilitaires électriques | B13: >430 000 ventes mondiales en 2025 | C13: IEA Global EV Outlook 2026 | D13: https://www.iea.org/reports/global-ev-outlook-2026/trends-in-other-ev-modes | E13: TAM marché professionnel
A14: Marché bus électriques | B14: ~70 000 ventes mondiales en 2025 | C14: IEA Global EV Outlook 2026 | D14: https://www.iea.org/reports/global-ev-outlook-2026/trends-in-other-ev-modes | E14: TAM marché professionnel
... A19: Brésil — modifications véhicules | B19: Autorisation préalable et exigences réglementaires selon modification | C19: CONTRAN / Gov.br | D19: https://www.gov.br/transportes/pt-br/assuntos/transito/conteudo-contran/resolucao-contran-no-916-de-28-de-marco-de-2022 | E19: Risque réglementaire pays

Sheet Dashboard
A1: SOLAR WRAP — Business Plan V2 | Prévisionnel 2027–2033
A2: Scénario central prudent | Beachhead: camions / remorques frigorifiques | déploiement: Europe → Australie / Chili → Afrique du Sud / Brésil | aucune licence OEM ni subvention non sécurisée | B2: Scénario central prudent | Beachhead: camions / remorques frigorifiques | modèle sans licences OEM ni subventions non sécurisées | C2: Scénario central prudent | Beachhead: camions / remorques frigorifiques | modèle sans licences OEM ni subventions non sécurisées | D2: Scénario central prudent | Beachhead: camions / remorques frigorifiques | modèle sans licences OEM ni subventions non sécurisées | E2: Scénario central prudent | Beachhead: camions / remorques frigorifiques | modèle sans licences OEM ni subventions non sécurisées | F2: Scénario central prudent | Beachhead: camions / remorques frigorifiques | modèle sans licences OEM ni subventions non sécurisées | G2: Scénario central prudent | Beachhead: camions / remorques frigorifiques | modèle sans licences OEM ni subventions non sécurisées | H2: Scénario central prudent | Beachhead: camions / remorques frigorifiques | modèle sans licences OEM ni subventions non sécurisées | I2: Scénario central prudent | Beachhead: camions / remorques frigorifiques | modèle sans licences OEM ni subventions non sécurisées
A3: CA 2030 | D3: CA 2033 | G3: EBITDA positif
A4: ='P&L'!F7/1000 -> 11.750356 | D4: ='P&L'!I7/1000 -> 51.699244 | G4: =Financement!C8 -> 2030
A5: M€ | D5: M€ | G5: année
A6: Marge EBITDA 2033 | D6: Besoin max financement | G6: Payback client
A7: ='P&L'!I20 -> 0.28393757 | D7: =Financement!C5/1000 -> 5.77992 | G7: ='Unit Economics'!C11 -> 4.2
A8: % | D8: M€ | G8: ans
A9: Unités cumulées | D9: CO2e évité / véhicule | G9: Part TAM 2033
A10: =SUM(Ventes!C7:I7) -> 12385 | D10: ='Unit Economics'!C12 -> 4.65 | G10: ='Marché mondial'!B17 -> 0.55555556
A11: véhicules | D11: t/an | G11: du TAM pro électrique 2025
A12: Trajectoire financière | B12: Trajectoire financière | C12: Trajectoire financière | D12: Trajectoire financière | E12: Trajectoire financière | F12: Trajectoire financière | G12: Trajectoire financière | H12: Trajectoire financière | I12: Trajectoire financière
A13: Indicateur | C13: 2027 | D13: 2028 | E13: 2029 | F13: 2030 | G13: 2031 | H13: 2032 | I13: 2033
A14: CA (M€) | C14: ='P&L'!C7/1000 -> 0.12 | D14: ='P&L'!D7/1000 -> 1.3301892 | E14: ='P&L'!E7/1000 -> 4.8879691 | F14: ='P&L'!F7/1000 -> 11.750356 | G14: ='P&L'!G7/1000 -> 23.154018 | H14: ='P&L'!H7/1000 -> 36.475241 | I14: ='P&L'!I7/1000 -> 51.699244
A15: EBITDA (M€) | C15: ='P&L'!C19/1000 -> -1.1075 | D15: ='P&L'!D19/1000 -> -1.2993391 | E15: ='P&L'!E19/1000 -> -0.72997623 | F15: ='P&L'!F19/1000 -> 0.9903025 | G15: ='P&L'!G19/1000 -> 4.4779153 | H15: ='P&L'!H19/1000 -> 9.0364551 | I15: ='P&L'!I19/1000 -> 14.679358
A16: Unités vendues | C16: =Ventes!C7 -> 15 | D16: =Ventes!D7 -> 120 | E16: =Ventes!E7 -> 450 | F16: =Ventes!F7 -> 1100 | G16: =Ventes!G7 -> 2200 | H16: =Ventes!H7 -> 3500 | I16: =Ventes!I7 -> 5000
A34: Lecture COMEX | B34: Lecture COMEX | C34: Lecture COMEX | D34: Lecture COMEX | E34: Lecture COMEX | F34: Lecture COMEX | G34: Lecture COMEX | H34: Lecture COMEX | I34: Lecture COMEX
A35: 1 | B35: Le cas central atteint l'EBITDA positif en 2030, avant d'entrer dans une phase de forte génération de cash.
A36: 2 | B36: Le besoin maximal de financement avant apports est d'environ 5,8 M€; le modèle prévoit 6,0 M€ de financement par tranches.
A37: 3 | B37: La rentabilité repose d'abord sur la marge hardware et le volume; SOLAR CONTROL améliore ensuite la récurrence et la valeur par client.
A38: 4 | B38: Le ROI client de référence est proche de 4 ans sur un usage frigorifique diesel/hybride prudent; il doit être confirmé sur prototype.
